ERROR 2016-04-19 09:11:02,921 base 25378 139792654264064 Internal Server Error: /anafora/
Traceback (most recent call last):
  File "/usr/local/lib/python2.7/dist-packages/django/core/handlers/base.py", line 134, in get_response
    resolver_match = resolver.resolve(request.path_info)
  File "/usr/local/lib/python2.7/dist-packages/django/core/urlresolvers.py", line 376, in resolve
    sub_match = pattern.resolve(new_path)
  File "/usr/local/lib/python2.7/dist-packages/django/core/urlresolvers.py", line 248, in resolve
    return ResolverMatch(self.callback, args, kwargs, self.name)
  File "/usr/local/lib/python2.7/dist-packages/django/core/urlresolvers.py", line 255, in callback
    self._callback = get_callable(self._callback_str)
  File "/usr/local/lib/python2.7/dist-packages/django/utils/lru_cache.py", line 100, in wrapper
    result = user_function(*args, **kwds)
  File "/usr/local/lib/python2.7/dist-packages/django/core/urlresolvers.py", line 115, in get_callable
    mod = import_module(mod_name)
  File "/usr/lib/python2.7/importlib/__init__.py", line 37, in import_module
    __import__(name)
  File "/home/anafora/anafora-1.0.0/src/main/annotate/views.py", line 30, in <module>
    AnaforaProjectManager.rootPath = settings.ANAFORA_PROJECT_FILE_ROOT
  File "/usr/local/lib/python2.7/dist-packages/django/conf/__init__.py", line 56, in __getattr__
    return getattr(self._wrapped, name)
AttributeError: 'Settings' object has no attribute 'ANAFORA_PROJECT_FILE_ROOT'
ERROR 2016-04-19 09:11:04,556 base 25379 139792645871360 Internal Server Error: /anafora/
Traceback (most recent call last):
  File "/usr/local/lib/python2.7/dist-packages/django/core/handlers/base.py", line 134, in get_response
    resolver_match = resolver.resolve(request.path_info)
  File "/usr/local/lib/python2.7/dist-packages/django/core/urlresolvers.py", line 376, in resolve
    sub_match = pattern.resolve(new_path)
  File "/usr/local/lib/python2.7/dist-packages/django/core/urlresolvers.py", line 248, in resolve
    return ResolverMatch(self.callback, args, kwargs, self.name)
  File "/usr/local/lib/python2.7/dist-packages/django/core/urlresolvers.py", line 255, in callback
    self._callback = get_callable(self._callback_str)
  File "/usr/local/lib/python2.7/dist-packages/django/utils/lru_cache.py", line 100, in wrapper
    result = user_function(*args, **kwds)
  File "/usr/local/lib/python2.7/dist-packages/django/core/urlresolvers.py", line 115, in get_callable
    mod = import_module(mod_name)
  File "/usr/lib/python2.7/importlib/__init__.py", line 37, in import_module
    __import__(name)
  File "/home/anafora/anafora-1.0.0/src/main/annotate/views.py", line 30, in <module>
    AnaforaProjectManager.rootPath = settings.ANAFORA_PROJECT_FILE_ROOT
  File "/usr/local/lib/python2.7/dist-packages/django/conf/__init__.py", line 56, in __getattr__
    return getattr(self._wrapped, name)
AttributeError: 'Settings' object has no attribute 'ANAFORA_PROJECT_FILE_ROOT'
ERROR 2016-04-19 09:21:30,935 base 26249 140497867745024 Internal Server Error: /anafora/
Traceback (most recent call last):
  File "/usr/local/lib/python2.7/dist-packages/django/core/handlers/base.py", line 134, in get_response
    resolver_match = resolver.resolve(request.path_info)
  File "/usr/local/lib/python2.7/dist-packages/django/core/urlresolvers.py", line 376, in resolve
    sub_match = pattern.resolve(new_path)
  File "/usr/local/lib/python2.7/dist-packages/django/core/urlresolvers.py", line 248, in resolve
    return ResolverMatch(self.callback, args, kwargs, self.name)
  File "/usr/local/lib/python2.7/dist-packages/django/core/urlresolvers.py", line 255, in callback
    self._callback = get_callable(self._callback_str)
  File "/usr/local/lib/python2.7/dist-packages/django/utils/lru_cache.py", line 100, in wrapper
    result = user_function(*args, **kwds)
  File "/usr/local/lib/python2.7/dist-packages/django/core/urlresolvers.py", line 115, in get_callable
    mod = import_module(mod_name)
  File "/usr/lib/python2.7/importlib/__init__.py", line 37, in import_module
    __import__(name)
  File "/home/anafora/anafora-1.0.0/src/main/annotate/views.py", line 30, in <module>
    AnaforaProjectManager.rootPath = settings.ANAFORA_PROJECT_FILE_ROOT
  File "/usr/local/lib/python2.7/dist-packages/django/conf/__init__.py", line 56, in __getattr__
    return getattr(self._wrapped, name)
AttributeError: 'Settings' object has no attribute 'ANAFORA_PROJECT_FILE_ROOT'
ERROR 2016-04-19 09:27:06,325 base 26249 140497800603392 Internal Server Error: /anafora/
Traceback (most recent call last):
  File "/usr/local/lib/python2.7/dist-packages/django/core/handlers/base.py", line 134, in get_response
    resolver_match = resolver.resolve(request.path_info)
  File "/usr/local/lib/python2.7/dist-packages/django/core/urlresolvers.py", line 376, in resolve
    sub_match = pattern.resolve(new_path)
  File "/usr/local/lib/python2.7/dist-packages/django/core/urlresolvers.py", line 248, in resolve
    return ResolverMatch(self.callback, args, kwargs, self.name)
  File "/usr/local/lib/python2.7/dist-packages/django/core/urlresolvers.py", line 255, in callback
    self._callback = get_callable(self._callback_str)
  File "/usr/local/lib/python2.7/dist-packages/django/utils/lru_cache.py", line 100, in wrapper
    result = user_function(*args, **kwds)
  File "/usr/local/lib/python2.7/dist-packages/django/core/urlresolvers.py", line 115, in get_callable
    mod = import_module(mod_name)
  File "/usr/lib/python2.7/importlib/__init__.py", line 37, in import_module
    __import__(name)
  File "/home/anafora/anafora-1.0.0/src/main/annotate/views.py", line 30, in <module>
    AnaforaProjectManager.rootPath = settings.ANAFORA_PROJECT_FILE_ROOT
  File "/usr/local/lib/python2.7/dist-packages/django/conf/__init__.py", line 56, in __getattr__
    return getattr(self._wrapped, name)
AttributeError: 'Settings' object has no attribute 'ANAFORA_PROJECT_FILE_ROOT'
ERROR 2016-04-19 09:28:49,345 base 26248 140497800603392 Internal Server Error: /anafora/
Traceback (most recent call last):
  File "/usr/local/lib/python2.7/dist-packages/django/core/handlers/base.py", line 134, in get_response
    resolver_match = resolver.resolve(request.path_info)
  File "/usr/local/lib/python2.7/dist-packages/django/core/urlresolvers.py", line 376, in resolve
    sub_match = pattern.resolve(new_path)
  File "/usr/local/lib/python2.7/dist-packages/django/core/urlresolvers.py", line 248, in resolve
    return ResolverMatch(self.callback, args, kwargs, self.name)
  File "/usr/local/lib/python2.7/dist-packages/django/core/urlresolvers.py", line 255, in callback
    self._callback = get_callable(self._callback_str)
  File "/usr/local/lib/python2.7/dist-packages/django/utils/lru_cache.py", line 100, in wrapper
    result = user_function(*args, **kwds)
  File "/usr/local/lib/python2.7/dist-packages/django/core/urlresolvers.py", line 115, in get_callable
    mod = import_module(mod_name)
  File "/usr/lib/python2.7/importlib/__init__.py", line 37, in import_module
    __import__(name)
  File "/home/anafora/anafora-1.0.0/src/main/annotate/views.py", line 30, in <module>
    AnaforaProjectManager.rootPath = settings.ANAFORA_PROJECT_FILE_ROOT
  File "/usr/local/lib/python2.7/dist-packages/django/conf/__init__.py", line 56, in __getattr__
    return getattr(self._wrapped, name)
AttributeError: 'Settings' object has no attribute 'ANAFORA_PROJECT_FILE_ROOT'
ERROR 2016-04-19 09:33:44,220 base 26249 140497783817984 Internal Server Error: /anafora/
Traceback (most recent call last):
  File "/usr/local/lib/python2.7/dist-packages/django/core/handlers/base.py", line 134, in get_response
    resolver_match = resolver.resolve(request.path_info)
  File "/usr/local/lib/python2.7/dist-packages/django/core/urlresolvers.py", line 376, in resolve
    sub_match = pattern.resolve(new_path)
  File "/usr/local/lib/python2.7/dist-packages/django/core/urlresolvers.py", line 248, in resolve
    return ResolverMatch(self.callback, args, kwargs, self.name)
  File "/usr/local/lib/python2.7/dist-packages/django/core/urlresolvers.py", line 255, in callback
    self._callback = get_callable(self._callback_str)
  File "/usr/local/lib/python2.7/dist-packages/django/utils/lru_cache.py", line 100, in wrapper
    result = user_function(*args, **kwds)
  File "/usr/local/lib/python2.7/dist-packages/django/core/urlresolvers.py", line 115, in get_callable
    mod = import_module(mod_name)
  File "/usr/lib/python2.7/importlib/__init__.py", line 37, in import_module
    __import__(name)
  File "/home/anafora/anafora-1.0.0/src/main/annotate/views.py", line 30, in <module>
    AnaforaProjectManager.rootPath = settings.ANAFORA_PROJECT_FILE_ROOT
  File "/usr/local/lib/python2.7/dist-packages/django/conf/__init__.py", line 56, in __getattr__
    return getattr(self._wrapped, name)
AttributeError: 'Settings' object has no attribute 'ANAFORA_PROJECT_FILE_ROOT'
ERROR 2016-04-19 09:37:51,731 base 26249 140497767032576 Internal Server Error: /anafora/
Traceback (most recent call last):
  File "/usr/local/lib/python2.7/dist-packages/django/core/handlers/base.py", line 134, in get_response
    resolver_match = resolver.resolve(request.path_info)
  File "/usr/local/lib/python2.7/dist-packages/django/core/urlresolvers.py", line 376, in resolve
    sub_match = pattern.resolve(new_path)
  File "/usr/local/lib/python2.7/dist-packages/django/core/urlresolvers.py", line 248, in resolve
    return ResolverMatch(self.callback, args, kwargs, self.name)
  File "/usr/local/lib/python2.7/dist-packages/django/core/urlresolvers.py", line 255, in callback
    self._callback = get_callable(self._callback_str)
  File "/usr/local/lib/python2.7/dist-packages/django/utils/lru_cache.py", line 100, in wrapper
    result = user_function(*args, **kwds)
  File "/usr/local/lib/python2.7/dist-packages/django/core/urlresolvers.py", line 115, in get_callable
    mod = import_module(mod_name)
  File "/usr/lib/python2.7/importlib/__init__.py", line 37, in import_module
    __import__(name)
  File "/home/anafora/anafora-1.0.0/src/main/annotate/views.py", line 30, in <module>
    AnaforaProjectManager.rootPath = settings.ANAFORA_PROJECT_FILE_ROOT
  File "/usr/local/lib/python2.7/dist-packages/django/conf/__init__.py", line 56, in __getattr__
    return getattr(self._wrapped, name)
AttributeError: 'Settings' object has no attribute 'ANAFORA_PROJECT_FILE_ROOT'
ERROR 2016-04-19 09:40:15,178 base 26660 140474404820736 Internal Server Error: /anafora/
Traceback (most recent call last):
  File "/usr/local/lib/python2.7/dist-packages/django/core/handlers/base.py", line 149, in get_response
    response = self.process_exception_by_middleware(e, request)
  File "/usr/local/lib/python2.7/dist-packages/django/core/handlers/base.py", line 147, in get_response
    response = wrapped_callback(request, *callback_args, **callback_kwargs)
  File "/home/anafora/anafora-1.0.0/src/main/annotate/views.py", line 70, in index
    ps = getProjectSetting()
  File "/home/anafora/anafora-1.0.0/src/main/annotate/views.py", line 363, in getProjectSetting
    projectSetting.parseFromFile(os.path.join(settings.ANAFORA_PROJECT_FILE_ROOT, settings.ANAFORA_PROJECT_SETTING_FILENAME))
  File "/home/anafora/anafora-1.0.0/src/main/annotate/projectSetting.py", line 12, in parseFromFile
    fhd = open(filePath)
IOError: [Errno 2] No such file or directory: '/home/anafora-1.0.0/sample data/sampleanaforaprojectfile/.setting.xml'
